Workbook

Sheet REGIÃO 1
A1: REGIÃO | B1: CIDADE | C1: NÚMERO DO TRECHO | D1: RODOVIA | E1: TRECHO | F1: SRE | G1: SEGMENTO | H1: SITUAÇÃO | I1: COORDENADA INICIAL | J1: COORDENADA FINAL | K1: EXTENSÃO REAL (km)
A2: 1 | B2: TOCANTINÓPOLIS | C2: 1 | D2: TO-010 | E2: RODOVIA TO-010 - TRECHO ANANÁS - ENTR. BR-230 | F2: 010ETO0512D | G2: ENTR. TO-210(PU ANANÁS) - FIM DUPLICAÇÃO(PU ANANÁS) | H2: PDU | I2: -48.06889555, -6.372561004 | J2: -48.073498298, -6.362406329 | K2: 1.4534031
A3: 1 | B3: TOCANTINÓPOLIS | C3: 1 | D3: TO-010 | E3: RODOVIA TO-010 - TRECHO ANANÁS - ENTR. BR-230 | F3: 010ETO0512E | G3: ENTR. TO-210(PU ANANÁS) - FIM DUPLICAÇÃO(PU ANANÁS) | H3: PDU | I3: -48.073406977, -6.362537882 | J3: -48.068827289, -6.372451746 | K3: 1.4186394
A4: 1 | B4: TOCANTINÓPOLIS | C4: 1 | D4: TO-010 | E4: RODOVIA TO-010 - TRECHO ANANÁS - ENTR. BR-230 | F4: 010ETO0522 | G4: FIM DUPLICAÇÃO(PU ANANÁS) - FIM PU ANANÁS | H4: PPS | I4: -48.076141, -6.358384 | J4: -48.073406977, -6.362537882 | K4: 0.55064504
A5: 1 | B5: TOCANTINÓPOLIS | C5: 1 | D5: TO-010 | E5: RODOVIA TO-010 - TRECHO ANANÁS - ENTR. BR-230 | F5: 010ETO0540 | G5: FIM PU ANANÁS - FIM PAVIMENTAÇÃO | H5: PPS | I5: -48.088389, -6.328514 | J5: -48.076141, -6.358384 | K5: 3.7177854
A6: 1 | B6: TOCANTINÓPOLIS | C6: 1 | D6: TO-010 | E6: RODOVIA TO-010 - TRECHO ANANÁS - ENTR. BR-230 | F6: 010ETO0542 | G6: FIM PAVIMENTAÇÃO - ENTR. TO-414(TAPUIO) | H6: EOP | I6: -48.088782, -6.327772 | J6: -48.088389, -6.328514 | K6: 0.093164237
A7: 1 | B7: TOCANTINÓPOLIS | C7: 1 | D7: TO-010 | E7: RODOVIA TO-010 - TRECHO ANANÁS - ENTR. BR-230 | F7: 010ETO0543 | G7: ENTR. TO-414(TAPUIO) - INÍCIO PAVIMENTAÇÃO | H7: EOP | I7: -48.089781, -6.325908 | J7: -48.088782, -6.327772 | K7: 0.23414638
A8: 1 | B8: TOCANTINÓPOLIS | C8: 1 | D8: TO-010 | E8: RODOVIA TO-010 - TRECHO ANANÁS - ENTR. BR-230 | F8: 010ETO0550 | G8: INÍCIO PAVIMENTAÇÃO - ENTR. TO-210 | H8: PPS | I8: -48.096642, -6.314958 | J8: -48.089781, -6.325908 | K8: 1.4307235
A9: 1 | B9: TOCANTINÓPOLIS | C9: 1 | D9: TO-010 | E9: RODOVIA TO-010 - TRECHO ANANÁS - ENTR. BR-230 | F9: 010ETO0555 | G9: ENTR. TO-210 - FIM PAVIMENTAÇÃO | H9: PPS | I9: -48.100065, -6.303139 | J9: -48.096642, -6.314958 | K9: 1.3976072
A10: 1 | B10: TOCANTINÓPOLIS | C10: 1 | D10: TO-010 | E10: RODOVIA TO-010 - TRECHO ANANÁS - ENTR. BR-230 | F10: 010ETO0560 | G10: FIM PAVIMENTACAO - ENTR. TO-205 | H10: EOP | I10: -48.123409, -6.058179 | J10: -48.100065, -6.303139 | K10: 32.133936
A11: 1 | B11: TOCANTINÓPOLIS | C11: 1 | D11: TO-010 | E11: RODOVIA TO-010 - TRECHO ANANÁS - ENTR. BR-230 | F11: 010ETO0570 | G11: ENTR. TO-205 - INÍCIO DUPLICAÇÃO(RONCA) | H11: EOP | I11: -48.146615944, -6.027752893 | J11: -48.123409, -6.058179 | K11: 4.9790284
A12: 1 | B12: TOCANTINÓPOLIS | C12: 1 | D12: TO-010 | E12: RODOVIA TO-010 - TRECHO ANANÁS - ENTR. BR-230 | F12: 010ETO0572D | G12: INÍCIO DUPLICAÇÃO(RONCA) - FIM DUPLICAÇÃO(FIM PU RONCA) | H12: PDU | I12: -48.148290217, -6.023744825 | J12: -48.146615944, -6.027752893 | K12: 0.48297461
A13: 1 | B13: TOCANTINÓPOLIS | C13: 1 | D13: TO-010 | E13: RODOVIA TO-010 - TRECHO ANANÁS - ENTR. BR-230 | F13: 010ETO0572E | G13: INÍCIO DUPLICAÇÃO(RONCA) - FIM DUPLICAÇÃO(FIM PU RONCA) | H13: PDU | I13: -48.146615944, -6.027752893 | J13: -48.148290217, -6.023744825 | K13: 0.48679077
... A214: 1 | B214: TOCANTINÓPOLIS | C214: 35 | D214: TO-415 | E214: RODOVIA TO-415 - TRECHO SANTA TEREZINHA DO TOCANTINS - PALMEIRAS DO TOCANTINS | F214: 415ETO0073E | G214: INÍCIO DUPLICAÇÃO(PU PALMEIRAS DO TOCANTINS) - ENTR. BR-226(PU PALMEIRAS DO TOCANTINS | H214: PDU | I214: -47.551318, -6.613186 | J214: -47.546357188, -6.613468118 | K214: 0.56733823

Sheet REGIÃO 2
A1: REGIÃO | B1: CIDADE | C1: NÚMERO DO TRECHO | D1: RODOVIA | E1: TRECHO | F1: SRE | G1: SEGMENTO | H1: SITUAÇÃO | I1: COORDENADA INICIAL | J1: COORDENADA FINAL | K1: EXTENSÃO REAL (km)
A2: 2 | B2: ARAGUAÍNA I | C2: 42 | D2: TO-164 | E2: RODOVIA TO-164 - TRECHO FÁBRICA DE CIMENTO - XAMBIOÁ - ENTR. BR-153 | F2: 164ETO0070 | G2: FABRICA DE CIMENTO - POV. CHAPADA | H2: PPS | I2: -48.453859, -6.416308 | J2: -48.429519, -6.428219 | K2: 3.1605539
A3: 2 | B3: ARAGUAÍNA I | C3: 42 | D3: TO-164 | E3: RODOVIA TO-164 - TRECHO FÁBRICA DE CIMENTO - XAMBIOÁ - ENTR. BR-153 | F3: 164ETO0082 | G3: INÍCIO PU POV. MANCHÃO DO MEIO - FIM PU POV. MANCHÃO DO MEIO | H3: PSU | I3: -48.505065, -6.410774 | J3: -48.502646, -6.411311 | K3: 0.27426814
A4: 2 | B4: ARAGUAÍNA I | C4: 42 | D4: TO-164 | E4: RODOVIA TO-164 - TRECHO FÁBRICA DE CIMENTO - XAMBIOÁ - ENTR. BR-153 | F4: 164ETO0080 | G4: POV. CHAPADA - INÍCIO PU POV. MANCHÃO DO MEIO | H4: PPS | I4: -48.502646, -6.411311 | J4: -48.453859, -6.416308 | K4: 5.7608589
A5: 2 | B5: ARAGUAÍNA I | C5: 42 | D5: TO-164 | E5: RODOVIA TO-164 - TRECHO FÁBRICA DE CIMENTO - XAMBIOÁ - ENTR. BR-153 | F5: 164ETO0090 | G5: FIM PU POV. MANCHÃO DO MEIO - INÍCIO PU XAMBIOÁ | H5: PPS | I5: -48.5230480026, -6.41493766786 | J5: -48.505065, -6.410774 | K5: 2.1595974
A6: 2 | B6: ARAGUAÍNA I | C6: 42 | D6: TO-164 | E6: RODOVIA TO-164 - TRECHO FÁBRICA DE CIMENTO - XAMBIOÁ - ENTR. BR-153 | F6: 164ETO0092 | G6: INÍCIO PU XAMBIOÁ - ENTR. BR-153(PU XAMBIOÁ) | H6: PPS | I6: -48.5333998792, -6.42008811555 | J6: -48.5230480026, -6.41493766786 | K6: 1.4051572
A7: 2 | B7: ARAGUAÍNA I | C7: 41 | D7: TO-164 | E7: RODOVIA TO-164 - TRECHO ENTR. BR-153 (XAMBIOÁ) - ARAGUANÃ | F7: 164ETO0095 | G7: FIM PU XAMBIOÁ - ENTR. TO-418(XAMBIOAZINHO) | H7: PPS | I7: -48.5409795923, -6.45237638918 | J7: -48.5364563569, -6.42491272168 | K7: 3.2547017
A8: 2 | B8: ARAGUAÍNA I | C8: 41 | D8: TO-164 | E8: RODOVIA TO-164 - TRECHO ENTR. BR-153 (XAMBIOÁ) - ARAGUANÃ | F8: 164ETO0100 | G8: ENTR. TO-418(XAMBIOAZINHO) - INÍCIO PU ARAGUANÃ | H8: PPS | I8: -48.5409795923, -6.45237638918 | J8: -48.639225, -6.570846 | K8: 19.097331
A9: 2 | B9: ARAGUAÍNA I | C9: 44 | D9: TO-164 | E9: RODOVIA TO-164 - TRECHO ARAGUANÃ - CARMOLÂNDIA | F9: 164ETO0110 | G9: FIM PU ARAGUANÃ - INÍCIO PU JACIlÂNDIA | H9: PPS | I9: -48.641603, -6.592737 | J9: -48.519944, -6.845185 | K9: 33.647287
A10: 2 | B10: ARAGUAÍNA I | C10: 59 | D10: TO-418 | E10: RODOVIA TO-418 - TRECHO ENTR. BR-153 - ENTR. TO-164 | F10: 418ETO0010 | G10: ENTR. TO-164 (XAMBIOAZINHO) - ENTR. BR-153 | H10: LEN | I10: -48.3585111, -6.61580268 | J10: -48.5409795923, -6.45237638918 | K10: 43.252906
A11: 2 | B11: ARAGUAÍNA I | C11: 44 | D11: TO-164 | E11: RODOVIA TO-164 - TRECHO ARAGUANÃ - CARMOLÂNDIA | F11: 164ETO0120 | G11: FIM PU JACILÂNDIA - INÍCIO PU CARMOLÂNDIA | H11: PPS | I11: -48.518161, -6.850281 | J11: -48.3972601543, -7.0291951805 | K11: 25.427926
A12: 2 | B12: ARAGUAÍNA I | C12: 45 | D12: TO-164 | E12: RODOVIA TO-164 - TRECHO CARMOLÂNDIA - ENTR. TO-222 - ARAGOMINAS | F12: 164ETO0130 | G12: FIM PU CARMOLÂNDIA - ENTR. TO-222(A)(PU NOVO HORIZONTE) | H12: PPS | I12: -48.393215, -7.041732 | J12: -48.343157, -7.185302 | K12: 17.048366
A13: 2 | B13: ARAGUAÍNA I | C13: 45 | D13: TO-164 | E13: RODOVIA TO-164 - TRECHO CARMOLÂNDIA - ENTR. TO-222 - ARAGOMINAS | F13: 164ETO0140 | G13: TO-222 (NOVO HORIZONTE) - ENTR. TO-419 (BRITADOR) | H13: PPS | I13: -48.4455069008, -7.19587343028 | J13: -48.343157, -7.185302 | K13: 11.974875
... A115: 2 | B115: ARAGUAÍNA I | C115: 55 | D115: TO-164 | E115: RODOVIA TO-230 - TRECHO BANDEIRANTES DO TOCANTINS - ARAPOEMA | F115: 164ETO0200 | G115: ENTR. TO-230(A) - INÍCIO PU DEZENOVE | H115: PSU | I115: -48.7920350475, -7.64059442114 | J115: -48.7962295118, -7.64085682353 | K115: 0.46401172

Sheet REGIÃO 3
A1: REGIÃO | B1: CIDADE | C1: NÚMERO DO TRECHO | D1: RODOVIA | E1: TRECHO | F1: SRE | G1: SEGMENTO | H1: SITUAÇÃO | I1: COORDENADA INICIAL | J1: COORDENADA FINAL | K1: EXTENSÃO REAL (km)
A2: 3 | B2: ARAGUAÍNA II | C2: 67 | D2: TO-010 | E2: RODOVIA TO-010 - TRECHO ENTR. BR-010 (ITACAJÁ) - PALMEIRANTE | F2: 010ETO0250 | G2: ENTR. BR-010 - ENTR. TO-226(POV. CAMPOS) | H2: LEN | I2: -47.743310178, -8.34099353348 | J2: -47.806618, -7.944864 | K2: 58.248007
A3: 3 | B3: ARAGUAÍNA II | C3: 67 | D3: TO-010 | E3: RODOVIA TO-010 - TRECHO ENTR. BR-010 (ITACAJÁ) - PALMEIRANTE | F3: 010ETO0290 | G3: ENTR. TO-226(POV. CAMPOS) - RIO TOCANTINS(BALSA PALMEIRANTE) | H3: LEN | I3: -47.8066177351, -7.94486429229 | J3: -47.9194950001, -7.861879 | K3: 19.463807
A4: 3 | B4: ARAGUAÍNA II | C4: 68 | D4: TO-010 | E4: RODOVIA TO-010 - TRECHO PALMEIRANTE - ENTR. TO-222 (POVOADO BIELÂNDIA) | F4: 010ETO0292 | G4: RIO TOCANTINS(BALSA PALMEIRANTE) - INÍCIO PAVIMENTAÇÃO(PU PALMEIRANTE) | H4: LEN | I4: -47.9227636647, -7.85696359067 | J4: -47.9222228365, -7.85813851311 | K4: 0.1431017
A5: 3 | B5: ARAGUAÍNA II | C5: 68 | D5: TO-010 | E5: RODOVIA TO-010 - TRECHO PALMEIRANTE - ENTR. TO-222 (POVOADO BIELÂNDIA) | F5: 010ETO0293 | G5: INÍCIO PAVIMENTAÇÃO(PU PALMEIRANTE) - INÍCIO DUPLICAÇÃO(PU PALMEIRANTE) | H5: PSU | I5: -47.9284597983, -7.85970837568 | J5: -47.9227636647, -7.85696359067 | K5: 0.69861505
A6: 3 | B6: ARAGUAÍNA II | C6: 68 | D6: TO-010 | E6: RODOVIA TO-010 - TRECHO PALMEIRANTE - ENTR. TO-222 (POVOADO BIELÂNDIA) | F6: 010ETO0295D | G6: INÍCIO DUPLICAÇÃO(PU PALMEIRANTE) - FIM DUPLICAÇÃO(PU PALMEIRANTE) | H6: PDU | I6: -47.9359380003, -7.86279899961 | J6: -47.9284597983, -7.85970837568 | K6: 0.90399369
A7: 3 | B7: ARAGUAÍNA II | C7: 68 | D7: TO-010 | E7: RODOVIA TO-010 - TRECHO PALMEIRANTE - ENTR. TO-222 (POVOADO BIELÂNDIA) | F7: 010ETO0295E | G7: INÍCIO DUPLICAÇÃO(PU PALMEIRANTE) - FIM DUPLICAÇÃO(PU PALMEIRANTE) | H7: PDU | I7: -47.9359380003, -7.86279899961 | J7: -47.9284597983, -7.85970837568 | K7: 0.89458118
A8: 3 | B8: ARAGUAÍNA II | C8: 68 | D8: TO-010 | E8: RODOVIA TO-010 - TRECHO PALMEIRANTE - ENTR. TO-222 (POVOADO BIELÂNDIA) | F8: 010ETO0297 | G8: FIM DUPLICAÇÃO(PU PALMEIRANTE) - FIM PU PALMEIRANTE | H8: PSU | I8: -47.9359380003, -7.86279899961 | J8: -47.939469, -7.86542700041 | K8: 0.49171944
A9: 3 | B9: ARAGUAÍNA II | C9: 68 | D9: TO-010 | E9: RODOVIA TO-010 - TRECHO PALMEIRANTE - ENTR. TO-222 (POVOADO BIELÂNDIA) | F9: 010ETO0320 | G9: FIM PU PALMEIRANTE - ENTR. TO-335 | H9: PPS | I9: -47.939469, -7.86542700041 | J9: -48.0196780004, -7.84706399994 | K9: 10.509162
A10: 3 | B10: ARAGUAÍNA II | C10: 68 | D10: TO-010 | E10: RODOVIA TO-010 - TRECHO PALMEIRANTE - ENTR. TO-222 (POVOADO BIELÂNDIA) | F10: 010ETO0330 | G10: ENTR. TO-335 - ENTR. TO-226 | H10: PPS | I10: -48.0196780004, -7.84706399994 | J10: -48.0717219996, -7.78855100029 | K10: 9.1482091
A11: 3 | B11: ARAGUAÍNA II | C11: 68 | D11: TO-010 | E11: RODOVIA TO-010 - TRECHO PALMEIRANTE - ENTR. TO-222 (POVOADO BIELÂNDIA) | F11: 010ETO0340 | G11: ENTR. TO-226 - POV. CICILÃNDIA | H11: PPS | I11: -48.0717219996, -7.78855100029 | J11: -48.0271119998, -7.69757199995 | K11: 11.53236
A12: 3 | B12: ARAGUAÍNA II | C12: 68 | D12: TO-010 | E12: RODOVIA TO-010 - TRECHO PALMEIRANTE - ENTR. TO-222 (POVOADO BIELÂNDIA) | F12: 010ETO0350 | G12: POV. CICILÃNDIA - ENTR. TO-130 | H12: PPS | I12: -48.0271119998, -7.69757199995 | J12: -47.8423730002, -7.60451099992 | K12: 25.888297
A13: 3 | B13: ARAGUAÍNA II | C13: 68 | D13: TO-010 | E13: RODOVIA TO-010 - TRECHO PALMEIRANTE - ENTR. TO-222 (POVOADO BIELÂNDIA) | F13: 010ETO0360 | G13: ENTR. TO-130(A) - INÍCIO DUPLICAÇÃO(PU BIELÂNDIA) | H13: PPS | I13: -47.8423730002, -7.60451099992 | J13: -47.85927, -7.48596199995 | K13: 14.539711
... A76: 3 | B76: ARAGUAÍNA II | C76: 71 | D76: TO-020 | E76: RODOVIA TO-020 - TRECHO RECURSOLÂNDIA - CAMPOS LINDOS | F76: 020ETO0200 | G76: BANDEIRA - ENTR. TO-428 (RANCHARIA) | H76: LEN | I76: -46.9518527877, -8.20009172071 | J76: -46.979201, -8.30440899955 | K76: 13.339037

Sheet REGIÃO 11
A1: REGIÃO | B1: CIDADE | C1: NÚMERO DO TRECHO | D1: RODOVIA | E1: TRECHO | F1: SRE | G1: SEGMENTO | H1: SITUAÇÃO | I1: COORDENADA INICIAL | J1: COORDENADA FINAL | K1: EXTENSÃO REAL (km)
A2: 11 | B2: GURUPI | C2: 204 | D2: TO-070 | E2: RODOVIA TO-070 - TRECHO ALIANÇA DO TOCANTINS - BREJINHO DE NAZARÉ | F2: 070ETO0122D | G2: INÍCIO DUPLICAÇÃO(PU ALIANÇA DO TOCANTINS) - ENTR. BR-153(A)(PU ALIANÇA DO TOCANTINS) | H2: PDU | I2: -48.9381628714, -11.3059464054 | J2: -48.9403478241, -11.3088906395 | K2: 0.40478042
A3: 11 | B3: GURUPI | C3: 204 | D3: TO-070 | E3: RODOVIA TO-070 - TRECHO ALIANÇA DO TOCANTINS - BREJINHO DE NAZARÉ | F3: 070ETO0122E | G3: INÍCIO DUPLICAÇÃO(PU ALIANÇA DO TOCANTINS) - ENTR. BR-153(A)(PU ALIANÇA DO TOCANTINS) | H3: PDU | I3: -48.9381628714, -11.3059464054 | J3: -48.9404515862, -11.3088232551 | K3: 0.42217452
A4: 11 | B4: GURUPI | C4: 204 | D4: TO-070 | E4: RODOVIA TO-070 - TRECHO ALIANÇA DO TOCANTINS - BREJINHO DE NAZARÉ | F4: 070ETO0116 | G4: ENTR. TO-362(A) - INÍCIO PU BREJINHO DE NAZARÉ | H4: PPS | I4: -48.5639047496, -11.0096609201 | J4: -48.56395345, -11.0063965585 | K4: 0.36206406
A5: 11 | B5: GURUPI | C5: 204 | D5: TO-070 | E5: RODOVIA TO-070 - TRECHO ALIANÇA DO TOCANTINS - BREJINHO DE NAZARÉ | F5: 070ETO0117 | G5: INÍCIO PU BREJINHO DE NAZARÉ - ENTR. TO-362(B)(PU BREJINHO DE NAZARÉ) | H5: PSU | I5: -48.5639047496, -11.0096609201 | J5: -48.5691119523, -11.0182940589 | K5: 1.1131042
A6: 11 | B6: GURUPI | C6: 204 | D6: TO-070 | E6: RODOVIA TO-070 - TRECHO ALIANÇA DO TOCANTINS - BREJINHO DE NAZARÉ | F6: 070ETO0118 | G6: ENTR. TO-362(B)(PU BREJINHO DE NAZARÉ) - FIM PU BREJINHO DE NAZARÉ | H6: PSU | I6: -48.5691119523, -11.0182940589 | J6: -48.5799119402, -11.0150828511 | K6: 1.2339761
A7: 11 | B7: GURUPI | C7: 204 | D7: TO-070 | E7: RODOVIA TO-070 - TRECHO ALIANÇA DO TOCANTINS - BREJINHO DE NAZARÉ | F7: 070ETO0120 | G7: FIM PU BREJINHO DE NAZARÉ - INÍCIO PU ALIANÇA DO TOCANTINS | H7: PPS | I7: -48.9273619154, -11.3037364801 | J7: -48.5799119402, -11.0150828511 | K7: 58.172192
A8: 11 | B8: GURUPI | C8: 204 | D8: TO-070 | E8: RODOVIA TO-070 - TRECHO ALIANÇA DO TOCANTINS - BREJINHO DE NAZARÉ | F8: 070ETO0121 | G8: INÍCIO PU ALIANÇA DO TOCANTINS - INÍCIO DUPLICAÇÃO(PU ALIANÇA DO TOCANTINS) | H8: PSU | I8: -48.9381628714, -11.3059464054 | J8: -48.9273619154, -11.3037364801 | K8: 1.2193473
A9: 11 | B9: GURUPI | C9: 205 | D9: TO-070 | E9: RODOVIA TO-070 - TRECHO DUERÉ - ALIANÇA DO TOCANTINS | F9: 070ETO0140 | G9: ENTR. BR-153(B) - ENTR. TO-164 | H9: PPS | I9: -48.939857, -11.297987 | J9: -49.1599896795, -11.2201307456 | K9: 26.917413
A10: 11 | B10: GURUPI | C10: 205 | D10: TO-070 | E10: RODOVIA TO-070 - TRECHO DUERÉ - ALIANÇA DO TOCANTINS | F10: 070ETO0150 | G10: ENTR. TO-164 - ENTR. TO-374 | H10: PPS | I10: -49.251884, -11.310701 | J10: -49.1599896795, -11.2201307456 | K10: 16.026923
A11: 11 | B11: GURUPI | C11: 205 | D11: TO-070 | E11: RODOVIA TO-070 - TRECHO DUERÉ - ALIANÇA DO TOCANTINS | F11: 070ETO0160 | G11: ENTR. TO-374 - INÍCIO PU DUERÉ | H11: PPS | I11: -49.26052, -11.330883 | J11: -49.251884, -11.310701 | K11: 2.7602049
A12: 11 | B12: GURUPI | C12: 205 | D12: TO-070 | E12: RODOVIA TO-070 - TRECHO DUERÉ - ALIANÇA DO TOCANTINS | F12: 070ETO0162 | G12: INÍCIO PU DUERÉ - ENTR. TO-483(PU DUERÉ) | H12: PSU | I12: -49.265577982, -11.3397205751 | J12: -49.26052, -11.330883 | K12: 1.1602987
A13: 11 | B13: GURUPI | C13: 205 | D13: TO-070 | E13: RODOVIA TO-070 - TRECHO DUERÉ - ALIANÇA DO TOCANTINS | F13: 070ETO0170 | G13: ENTR. TO-483(PU DUERÉ) - FIM PU DUERÉ | H13: PSU | I13: -49.2694616029, -11.3495976881 | J13: -49.265577982, -11.3397205751 | K13: 1.3510478
... A70: 11 | B70: GURUPI | C70: 207 | D70: ACESSO | E70: ACESSO | F70: ACESSO02 | G70: ENTR. TO-181 - ENTR. TO-255(PU LAGOA DA CONFUSÃO) | H70: LEN | I70: -49.6976227777778, -10.8407555573094 | J70: -49.9100038511586, -10.9090845346253 | K70: 27.438217

Sheet REGIÃO 12
A1: REGIÃO | B1: CIDADE | C1: NÚMERO DO TRECHO | D1: RODOVIA | E1: TRECHO | F1: SRE | G1: SEGMENTO | H1: SITUAÇÃO | I1: COORDENADA INICIAL | J1: COORDENADA FINAL | K1: EXTENSÃO REAL (km)
A2: 12 | B2: PEIXE | C2: 224 | D2: TO-141 | E2: RODOVIA TO-141 - TRECHO PALMEIRÓPOLIS - DIVISA TO-GO | F2: 141ETO0107 | G2: FIM DUPLICAÇÃO(PU PALMEIRÓPOLIS) - FIM PU PALMEIRÓPOLIS | H2: PSU | I2: -48.3916491232, -13.0520511684 | J2: -48.3983568585, -13.0425886359 | K2: 1.3137885
A3: 12 | B3: PEIXE | C3: 224 | D3: TO-141 | E3: RODOVIA TO-141 - TRECHO PALMEIRÓPOLIS - DIVISA TO-GO | F3: 141ETO0110 | G3: FIM PU PALMEIRÓPOLIS - DIV. TO/GO | H3: PPS | I3: -48.3916491232, -13.0520511684 | J3: -48.3883446591, -13.2623720664 | K3: 26.31938
A4: 12 | B4: PEIXE | C4: 224 | D4: TO-141 | E4: RODOVIA TO-141 - TRECHO PALMEIRÓPOLIS - DIVISA TO-GO | F4: 141ETO0105D | G4: ENTR. TO-387(INÍCIO DUPLICAÇÃO)(PU PALMEIRÓPOLIS) - FIM DUPLICAÇÃO(PU PALMEIRÓPOLIS) | H4: PDU | I4: -48.4073671733, -13.0424462039 | J4: -48.3983568585, -13.0425886359 | K4: 0.97804727
A5: 12 | B5: PEIXE | C5: 224 | D5: TO-141 | E5: RODOVIA TO-141 - TRECHO PALMEIRÓPOLIS - DIVISA TO-GO | F5: 141ETO0105E | G5: ENTR. TO-387(INÍCIO DUPLICAÇÃO)(PU PALMEIRÓPOLIS) - FIM DUPLICAÇÃO(PU PALMEIRÓPOLIS) | H5: PDU | I5: -48.4073671733, -13.0424462039 | J5: -48.3983568585, -13.0425886359 | K5: 0.98637492
A6: 12 | B6: PEIXE | C6: 225 | D6: TO-280 | E6: RODOVIA TO-280 - TRECHO NATIVIDADE - ALMAS | F6: 280ETO0150 | G6: ENTR. TO-040 (ALMAS) - ENTR. BR-010-TO-050 | H6: PPS | I6: -47.168445, -11.560857 | J6: -47.722667, -11.687714 | K6: 76.278218
A7: 12 | B7: PEIXE | C7: 226 | D7: TO-280 | E7: RODOVIA TO-280 - TRECHO SÃO VALÉRIO DE NATIVIDADE - NATIVIDADE | F7: 280ETO0190 | G7: ENTR. TO-482 - INÍCIO PU SÃO VALÉRIO DA NATIVIDADE | H7: PPS | I7: -48.230608, -11.964667 | J7: -48.172958, -11.917976 | K7: 8.3481121
A8: 12 | B8: PEIXE | C8: 226 | D8: TO-280 | E8: RODOVIA TO-280 - TRECHO SÃO VALÉRIO DE NATIVIDADE - NATIVIDADE | F8: 280ETO0180 | G8: ENTR. TO-486 - ENTR. TO-482 | H8: PPS | I8: -48.172958, -11.917976 | J8: -47.762698, -11.721811 | K8: 52.972294
A9: 12 | B9: PEIXE | C9: 226 | D9: TO-280 | E9: RODOVIA TO-280 - TRECHO SÃO VALÉRIO DE NATIVIDADE - NATIVIDADE | F9: 280ETO0175 | G9: FIM PU NATIVIDADE - ENTR. TO-486 | H9: PPS | I9: -47.762698, -11.721811 | J9: -47.74155, -11.715129 | K9: 2.4287741
A10: 12 | B10: PEIXE | C10: 226 | D10: TO-280 | E10: RODOVIA TO-280 - TRECHO SÃO VALÉRIO DE NATIVIDADE - NATIVIDADE | F10: 280ETO0152 | G10: ENTR. BR-010(B)/TO-050(A)(PU NATIVIDADE) - ENTR. BR-010(A)/TO-050(B)(PU NATIVIDADE) | H10: PSU | I10: -47.722667, -11.687714 | J10: -47.731711, -11.712532 | K10: 3.0905244
A11: 12 | B11: PEIXE | C11: 226 | D11: TO-280 | E11: RODOVIA TO-280 - TRECHO SÃO VALÉRIO DE NATIVIDADE - NATIVIDADE | F11: 280ETO0153 | G11: ENTR. BR-010(A)/TO-050(B)(PU NATIVIDADE) - FIM PU NATIVIDADE | H11: PSU | I11: -47.74155, -11.715129 | J11: -47.731711, -11.712532 | K11: 1.1172308
A12: 12 | B12: PEIXE | C12: 227 | D12: TO-280 | E12: RODOVIA TO-280 - TRECHO ENTR. BR-242 - SÃO VALÉRIO DE NATIVIDADE | F12: 280ETO0220 | G12: ENTR. TO-373 - ENTR. BR-242 | H12: PPS | I12: -48.32445, -12.018143 | J12: -48.443263, -12.151418 | K12: 21.414679
A13: 12 | B13: PEIXE | C13: 227 | D13: TO-280 | E13: RODOVIA TO-280 - TRECHO ENTR. BR-242 - SÃO VALÉRIO DE NATIVIDADE | F13: 280ETO0210 | G13: ENTR. TO-490 - ENTR. TO-373 | H13: PPS | I13: -48.242908, -11.990464 | J13: -48.32445, -12.018143 | K13: 9.5427994
... A73: 12 | B73: PEIXE | C73: 244 | D73: TO-498 | E73: RODOVIA TO-498 - TRECHO JAÚ DO TOCANTINS - ENTR. TO-387 | F73: 498ETO0050 | G73: FIM PU JAÚ DO TOCANTINS - INÍCIO DUPLICAÇÃO PU POV. NOVO HORIZONTE | H73: PPS | I73: -48.588621, -12.656774 | J73: -48.5785166476, -12.8359825107 | K73: 20.634399

Sheet REGIÃO 13
A1: REGIÃO | B1: CIDADE | C1: NÚMERO DO TRECHO | D1: RODOVIA | E1: TRECHO | F1: SRE | G1: SEGMENTO | H1: SITUAÇÃO | I1: COORDENADA INICIAL | J1: COORDENADA FINAL | K1: EXTENSÃO REAL (km)
A2: 13 | B2: DIANÓPOLIS | C2: 245 | D2: TO-040 | E2: RODOVIA TO-040 - TRECHO ENTR. TO-369 - ENTR. TO-280 (ALMAS) | F2: 040ETO0140 | G2: ENTR. TO-369 - ENTR. TO-280(PU ALMAS) | H2: LEN | I2: -47.2994875886, -11.1638440072 | J2: -47.1684449999, -11.560857 | K2: 56.641101
A3: 13 | B3: DIANÓPOLIS | C3: 246 | D3: TO-040 | E3: RODOVIA TO-040 - TRECHO ALMAS - PORTO ALEGRE DO TOCANTINS | F3: 040ETO0150 | G3: ENTR. TO-280(PU ALMAS) - ENTR. TO-477(PU ALMAS) | H3: PSU | I3: -47.1684449999, -11.560857 | J3: -47.1549759545, -11.5621995971 | K3: 1.5412653
A4: 13 | B4: DIANÓPOLIS | C4: 246 | D4: TO-040 | E4: RODOVIA TO-040 - TRECHO ALMAS - PORTO ALEGRE DO TOCANTINS | F4: 040ETO0160 | G4: ENTR. TO-477(PU ALMAS) - INÍCIO PU PORTO ALEGRE DO TOCANTINS | H4: PPS | I4: -47.1548380002, -11.5624670005 | J4: -47.0554309998, -11.6109339998 | K4: 12.788514
A5: 13 | B5: DIANÓPOLIS | C5: 246 | D5: TO-040 | E5: RODOVIA TO-040 - TRECHO ALMAS - PORTO ALEGRE DO TOCANTINS | F5: 040ETO0162 | G5: INÍCIO PU PORTO ALEGRE DO TOCANTINS - RIO MANUEL ALVES(FIM PU PORTO ALEGRE DO TOCANTINS) | H5: PSU | I5: -47.0554309998, -11.6109339998 | J5: -47.0446269998, -11.612616 | K5: 1.1933733
A6: 13 | B6: DIANÓPOLIS | C6: 247 | D6: TO-040 | E6: RODOVIA TO-040 - TRECHO DIANÓPOLIS - NOVO JARDIM | F6: 040ETO0187 | G6: ENTR. TO-476(PU DIANÓPOLIS) - PU DIANÓPOLIS | H6: PPS | I6: -46.8320609999, -11.6135089998 | J6: -46.8241100002, -11.6132460003 | K6: 0.89941253
A7: 13 | B7: DIANÓPOLIS | C7: 247 | D7: TO-040 | E7: RODOVIA TO-040 - TRECHO DIANÓPOLIS - NOVO JARDIM | F7: 040ETO0190 | G7: PU DIANÓPOLIS - ENTR. TO-110(A)/TO-387(A) | H7: PPS | I7: -46.8241100002, -11.6132460003 | J7: -46.7781900005, -11.6278609998 | K7: 5.3822208
A8: 13 | B8: DIANÓPOLIS | C8: 247 | D8: TO-040 | E8: RODOVIA TO-040 - TRECHO DIANÓPOLIS - NOVO JARDIM | F8: 040ETO0200 | G8: ENTR. TO-110(A)/TO-387(A) - INÍCIO PU POV. AMARALINA | H8: PPS | I8: -46.7781900005, -11.6278609998 | J8: -46.7417990004, -11.7105590003 | K8: 10.724633
A9: 13 | B9: DIANÓPOLIS | C9: 247 | D9: TO-040 | E9: RODOVIA TO-040 - TRECHO DIANÓPOLIS - NOVO JARDIM | F9: 040ETO0202 | G9: INÍCIO PU POV. AMARALINA - FIM PU POV. AMARALINA | H9: PSU | I9: -46.7417990004, -11.7105590003 | J9: -46.7410740003, -11.7201459999 | K9: 1.066343
A10: 13 | B10: DIANÓPOLIS | C10: 247 | D10: TO-040 | E10: RODOVIA TO-040 - TRECHO DIANÓPOLIS - NOVO JARDIM | F10: 040ETO0210 | G10: FIM PU POV. AMARALINA - INÍCIO PU NOVO JARDIM | H10: PPS | I10: -46.7410740003, -11.7201459999 | J10: -46.6261330003, -11.8176339999 | K10: 17.74312
A11: 13 | B11: DIANÓPOLIS | C11: 247 | D11: TO-040 | E11: RODOVIA TO-040 - TRECHO DIANÓPOLIS - NOVO JARDIM | F11: 040ETO0212 | G11: INÍCIO PU NOVO JARDIM - FIM PU NOVO JARDIM | H11: PPS | I11: -46.6261330003, -11.8176339999 | J11: -46.6210025886, -11.8210382258 | K11: 0.69527949
A12: 13 | B12: DIANÓPOLIS | C12: 248 | D12: TO-040 | E12: RODOVIA TO-040 - TRECHO NOVO JARDIM - DIVISA TO-BA | F12: 040ETO0220 | G12: FIM PU NOVO JARDIM - ENTR. TO-110(B) | H12: PPS | I12: -46.6210025886, -11.8210382258 | J12: -46.5809680004, -11.8324660004 | K12: 5.2583213
A13: 13 | B13: DIANÓPOLIS | C13: 248 | D13: TO-040 | E13: RODOVIA TO-040 - TRECHO NOVO JARDIM - DIVISA TO-BA | F13: 040ETO0230 | G13: ENTR. TO-110(B) - DIV. TO/BA | H13: PPS | I13: -46.2977762913, -11.8337762425 | J13: -46.5809680004, -11.8324660004 | K13: 36.978128
... A110: 13 | B110: DIANÓPOLIS | C110: 273 | D110: TO-499 | E110: RODOVIA TO-499 - TRECHO ENTR. TO-050 - DIVISA TO-GO | F110: 499ETO0010 | G110: ENTR. TO-050 - DIV. TO/GO | H110: LEN | I110: -46.8698620002, -13.0624039999 | J110: -46.9023530003, -12.9722459999 | K110: 11.182941

Sheet BASE CONSOLIDADA
A1: REGIÃO | B1: CIDADE | C1: NÚMERO DO TRECHO | D1: RODOVIA | E1: TRECHO | F1: SRE | G1: SEGMENTO | H1: SITUAÇÃO | I1: COORDENADA INICIAL | J1: COORDENADA FINAL | K1: EXTENSÃO REAL (km) | L1: ABA ORIGEM
A2: ='REGIÃO 1'!A2 | B2: ='REGIÃO 1'!B2 | C2: ='REGIÃO 1'!C2 | D2: ='REGIÃO 1'!D2 | E2: ='REGIÃO 1'!E2 | F2: ='REGIÃO 1'!F2 | G2: ='REGIÃO 1'!G2 | H2: ='REGIÃO 1'!H2 | ... K2: ='REGIÃO 1'!K2 | L2: REGIÃO 1
A3: ='REGIÃO 1'!A3 | B3: ='REGIÃO 1'!B3 | C3: ='REGIÃO 1'!C3 | D3: ='REGIÃO 1'!D3 | E3: ='REGIÃO 1'!E3 | F3: ='REGIÃO 1'!F3 | G3: ='REGIÃO 1'!G3 | H3: ='REGIÃO 1'!H3 | ... K3: ='REGIÃO 1'!K3 | L3: REGIÃO 1
A4: ='REGIÃO 1'!A4 | B4: ='REGIÃO 1'!B4 | C4: ='REGIÃO 1'!C4 | D4: ='REGIÃO 1'!D4 | E4: ='REGIÃO 1'!E4 | F4: ='REGIÃO 1'!F4 | G4: ='REGIÃO 1'!G4 | H4: ='REGIÃO 1'!H4 | ... K4: ='REGIÃO 1'!K4 | L4: REGIÃO 1
A5: ='REGIÃO 1'!A5 | B5: ='REGIÃO 1'!B5 | C5: ='REGIÃO 1'!C5 | D5: ='REGIÃO 1'!D5 | E5: ='REGIÃO 1'!E5 | F5: ='REGIÃO 1'!F5 | G5: ='REGIÃO 1'!G5 | H5: ='REGIÃO 1'!H5 | ... K5: ='REGIÃO 1'!K5 | L5: REGIÃO 1
A6: ='REGIÃO 1'!A6 | B6: ='REGIÃO 1'!B6 | C6: ='REGIÃO 1'!C6 | D6: ='REGIÃO 1'!D6 | E6: ='REGIÃO 1'!E6 | F6: ='REGIÃO 1'!F6 | G6: ='REGIÃO 1'!G6 | H6: ='REGIÃO 1'!H6 | ... K6: ='REGIÃO 1'!K6 | L6: REGIÃO 1
A7: ='REGIÃO 1'!A7 | B7: ='REGIÃO 1'!B7 | C7: ='REGIÃO 1'!C7 | D7: ='REGIÃO 1'!D7 | E7: ='REGIÃO 1'!E7 | F7: ='REGIÃO 1'!F7 | G7: ='REGIÃO 1'!G7 | H7: ='REGIÃO 1'!H7 | ... K7: ='REGIÃO 1'!K7 | L7: REGIÃO 1
A8: ='REGIÃO 1'!A8 | B8: ='REGIÃO 1'!B8 | C8: ='REGIÃO 1'!C8 | D8: ='REGIÃO 1'!D8 | E8: ='REGIÃO 1'!E8 | F8: ='REGIÃO 1'!F8 | G8: ='REGIÃO 1'!G8 | H8: ='REGIÃO 1'!H8 | ... K8: ='REGIÃO 1'!K8 | L8: REGIÃO 1
A9: ='REGIÃO 1'!A9 | B9: ='REGIÃO 1'!B9 | C9: ='REGIÃO 1'!C9 | D9: ='REGIÃO 1'!D9 | E9: ='REGIÃO 1'!E9 | F9: ='REGIÃO 1'!F9 | G9: ='REGIÃO 1'!G9 | H9: ='REGIÃO 1'!H9 | ... K9: ='REGIÃO 1'!K9 | L9: REGIÃO 1
A10: ='REGIÃO 1'!A10 | B10: ='REGIÃO 1'!B10 | C10: ='REGIÃO 1'!C10 | D10: ='REGIÃO 1'!D10 | E10: ='REGIÃO 1'!E10 | F10: ='REGIÃO 1'!F10 | G10: ='REGIÃO 1'!G10 | H10: ='REGIÃO 1'!H10 | ... K10: ='REGIÃO 1'!K10 | L10: REGIÃO 1
A11: ='REGIÃO 1'!A11 | B11: ='REGIÃO 1'!B11 | C11: ='REGIÃO 1'!C11 | D11: ='REGIÃO 1'!D11 | E11: ='REGIÃO 1'!E11 | F11: ='REGIÃO 1'!F11 | G11: ='REGIÃO 1'!G11 | H11: ='REGIÃO 1'!H11 | ... K11: ='REGIÃO 1'!K11 | L11: REGIÃO 1
A12: ='REGIÃO 1'!A12 | B12: ='REGIÃO 1'!B12 | C12: ='REGIÃO 1'!C12 | D12: ='REGIÃO 1'!D12 | E12: ='REGIÃO 1'!E12 | F12: ='REGIÃO 1'!F12 | G12: ='REGIÃO 1'!G12 | H12: ='REGIÃO 1'!H12 | ... K12: ='REGIÃO 1'!K12 | L12: REGIÃO 1
A13: ='REGIÃO 1'!A13 | B13: ='REGIÃO 1'!B13 | C13: ='REGIÃO 1'!C13 | D13: ='REGIÃO 1'!D13 | E13: ='REGIÃO 1'!E13 | F13: ='REGIÃO 1'!F13 | G13: ='REGIÃO 1'!G13 | H13: ='REGIÃO 1'!H13 | ... K13: ='REGIÃO 1'!K13 | L13: REGIÃO 1
... A214: ='REGIÃO 1'!A214 | B214: ='REGIÃO 1'!B214 | C214: ='REGIÃO 1'!C214 | D214: ='REGIÃO 1'!D214 | E214: ='REGIÃO 1'!E214 | F214: ='REGIÃO 1'!F214 | G214: ='REGIÃO 1'!G214 | H214: ='REGIÃO 1'!H214 | ... K214: ='REGIÃO 1'!K214 | L214: REGIÃO 1
A215: ='REGIÃO 2'!A2 | B215: ='REGIÃO 2'!B2 | C215: ='REGIÃO 2'!C2 | D215: ='REGIÃO 2'!D2 | E215: ='REGIÃO 2'!E2 | F215: ='REGIÃO 2'!F2 | G215: ='REGIÃO 2'!G2 | H215: ='REGIÃO 2'!H2 | ... K215: ='REGIÃO 2'!K2 | L215: REGIÃO 2
A216: ='REGIÃO 2'!A3 | B216: ='REGIÃO 2'!B3 | C216: ='REGIÃO 2'!C3 | D216: ='REGIÃO 2'!D3 | E216: ='REGIÃO 2'!E3 | F216: ='REGIÃO 2'!F3 | G216: ='REGIÃO 2'!G3 | H216: ='REGIÃO 2'!H3 | ... K216: ='REGIÃO 2'!K3 | L216: REGIÃO 2
A217: ='REGIÃO 2'!A4 | B217: ='REGIÃO 2'!B4 | C217: ='REGIÃO 2'!C4 | D217: ='REGIÃO 2'!D4 | E217: ='REGIÃO 2'!E4 | F217: ='REGIÃO 2'!F4 | G217: ='REGIÃO 2'!G4 | H217: ='REGIÃO 2'!H4 | ... K217: ='REGIÃO 2'!K4 | L217: REGIÃO 2
A218: ='REGIÃO 2'!A5 | B218: ='REGIÃO 2'!B5 | C218: ='REGIÃO 2'!C5 | D218: ='REGIÃO 2'!D5 | E218: ='REGIÃO 2'!E5 | F218: ='REGIÃO 2'!F5 | G218: ='REGIÃO 2'!G5 | H218: ='REGIÃO 2'!H5 | ... K218: ='REGIÃO 2'!K5 | L218: REGIÃO 2
A219: ='REGIÃO 2'!A6 | B219: ='REGIÃO 2'!B6 | C219: ='REGIÃO 2'!C6 | D219: ='REGIÃO 2'!D6 | E219: ='REGIÃO 2'!E6 | F219: ='REGIÃO 2'!F6 | G219: ='REGIÃO 2'!G6 | H219: ='REGIÃO 2'!H6 | ... K219: ='REGIÃO 2'!K6 | L219: REGIÃO 2
A220: ='REGIÃO 2'!A7 | B220: ='REGIÃO 2'!B7 | C220: ='REGIÃO 2'!C7 | D220: ='REGIÃO 2'!D7 | E220: ='REGIÃO 2'!E7 | F220: ='REGIÃO 2'!F7 | G220: ='REGIÃO 2'!G7 | H220: ='REGIÃO 2'!H7 | ... K220: ='REGIÃO 2'!K7 | L220: REGIÃO 2
A221: ='REGIÃO 2'!A8 | B221: ='REGIÃO 2'!B8 | C221: ='REGIÃO 2'!C8 | D221: ='REGIÃO 2'!D8 | E221: ='REGIÃO 2'!E8 | F221: ='REGIÃO 2'!F8 | G221: ='REGIÃO 2'!G8 | H221: ='REGIÃO 2'!H8 | ... K221: ='REGIÃO 2'!K8 | L221: REGIÃO 2
A222: ='REGIÃO 2'!A9 | B222: ='REGIÃO 2'!B9 | C222: ='REGIÃO 2'!C9 | D222: ='REGIÃO 2'!D9 | E222: ='REGIÃO 2'!E9 | F222: ='REGIÃO 2'!F9 | G222: ='REGIÃO 2'!G9 | H222: ='REGIÃO 2'!H9 | ... K222: ='REGIÃO 2'!K9 | L222: REGIÃO 2
A223: ='REGIÃO 2'!A10 | B223: ='REGIÃO 2'!B10 | C223: ='REGIÃO 2'!C10 | D223: ='REGIÃO 2'!D10 | E223: ='REGIÃO 2'!E10 | F223: ='REGIÃO 2'!F10 | G223: ='REGIÃO 2'!G10 | H223: ='REGIÃO 2'!H10 | ... K223: ='REGIÃO 2'!K10 | L223: REGIÃO 2
A224: ='REGIÃO 2'!A11 | B224: ='REGIÃO 2'!B11 | C224: ='REGIÃO 2'!C11 | D224: ='REGIÃO 2'!D11 | E224: ='REGIÃO 2'!E11 | F224: ='REGIÃO 2'!F11 | G224: ='REGIÃO 2'!G11 | H224: ='REGIÃO 2'!H11 | ... K224: ='REGIÃO 2'!K11 | L224: REGIÃO 2
A225: ='REGIÃO 2'!A12 | B225: ='REGIÃO 2'!B12 | C225: ='REGIÃO 2'!C12 | D225: ='REGIÃO 2'!D12 | E225: ='REGIÃO 2'!E12 | F225: ='REGIÃO 2'!F12 | G225: ='REGIÃO 2'!G12 | H225: ='REGIÃO 2'!H12 | ... K225: ='REGIÃO 2'!K12 | L225: REGIÃO 2
A226: ='REGIÃO 2'!A13 | B226: ='REGIÃO 2'!B13 | C226: ='REGIÃO 2'!C13 | D226: ='REGIÃO 2'!D13 | E226: ='REGIÃO 2'!E13 | F226: ='REGIÃO 2'!F13 | G226: ='REGIÃO 2'!G13 | H226: ='REGIÃO 2'!H13 | ... K226: ='REGIÃO 2'!K13 | L226: REGIÃO 2
... A328: ='REGIÃO 2'!A115 | B328: ='REGIÃO 2'!B115 | C328: ='REGIÃO 2'!C115 | D328: ='REGIÃO 2'!D115 | E328: ='REGIÃO 2'!E115 | F328: ='REGIÃO 2'!F115 | G328: ='REGIÃO 2'!G115 | H328: ='REGIÃO 2'!H115 | ... K328: ='REGIÃO 2'!K115 | L328: REGIÃO 2
A329: ='REGIÃO 3'!A2 | B329: ='REGIÃO 3'!B2 | C329: ='REGIÃO 3'!C2 | D329: ='REGIÃO 3'!D2 | E329: ='REGIÃO 3'!E2 | F329: ='REGIÃO 3'!F2 | G329: ='REGIÃO 3'!G2 | H329: ='REGIÃO 3'!H2 | ... K329: ='REGIÃO 3'!K2 | L329: REGIÃO 3
A330: ='REGIÃO 3'!A3 | B330: ='REGIÃO 3'!B3 | C330: ='REGIÃO 3'!C3 | D330: ='REGIÃO 3'!D3 | E330: ='REGIÃO 3'!E3 | F330: ='REGIÃO 3'!F3 | G330: ='REGIÃO 3'!G3 | H330: ='REGIÃO 3'!H3 | ... K330: ='REGIÃO 3'!K3 | L330: REGIÃO 3
A331: ='REGIÃO 3'!A4 | B331: ='REGIÃO 3'!B4 | C331: ='REGIÃO 3'!C4 | D331: ='REGIÃO 3'!D4 | E331: ='REGIÃO 3'!E4 | F331: ='REGIÃO 3'!F4 | G331: ='REGIÃO 3'!G4 | H331: ='REGIÃO 3'!H4 | ... K331: ='REGIÃO 3'!K4 | L331: REGIÃO 3
A332: ='REGIÃO 3'!A5 | B332: ='REGIÃO 3'!B5 | C332: ='REGIÃO 3'!C5 | D332: ='REGIÃO 3'!D5 | E332: ='REGIÃO 3'!E5 | F332: ='REGIÃO 3'!F5 | G332: ='REGIÃO 3'!G5 | H332: ='REGIÃO 3'!H5 | ... K332: ='REGIÃO 3'!K5 | L332: REGIÃO 3
A333: ='REGIÃO 3'!A6 | B333: ='REGIÃO 3'!B6 | C333: ='REGIÃO 3'!C6 | D333: ='REGIÃO 3'!D6 | E333: ='REGIÃO 3'!E6 | F333: ='REGIÃO 3'!F6 | G333: ='REGIÃO 3'!G6 | H333: ='REGIÃO 3'!H6 | ... K333: ='REGIÃO 3'!K6 | L333: REGIÃO 3
A334: ='REGIÃO 3'!A7 | B334: ='REGIÃO 3'!B7 | C334: ='REGIÃO 3'!C7 | D334: ='REGIÃO 3'!D7 | E334: ='REGIÃO 3'!E7 | F334: ='REGIÃO 3'!F7 | G334: ='REGIÃO 3'!G7 | H334: ='REGIÃO 3'!H7 | ... K334: ='REGIÃO 3'!K7 | L334: REGIÃO 3
A335: ='REGIÃO 3'!A8 | B335: ='REGIÃO 3'!B8 | C335: ='REGIÃO 3'!C8 | D335: ='REGIÃO 3'!D8 | E335: ='REGIÃO 3'!E8 | F335: ='REGIÃO 3'!F8 | G335: ='REGIÃO 3'!G8 | H335: ='REGIÃO 3'!H8 | ... K335: ='REGIÃO 3'!K8 | L335: REGIÃO 3
A336: ='REGIÃO 3'!A9 | B336: ='REGIÃO 3'!B9 | C336: ='REGIÃO 3'!C9 | D336: ='REGIÃO 3'!D9 | E336: ='REGIÃO 3'!E9 | F336: ='REGIÃO 3'!F9 | G336: ='REGIÃO 3'!G9 | H336: ='REGIÃO 3'!H9 | ... K336: ='REGIÃO 3'!K9 | L336: REGIÃO 3
A337: ='REGIÃO 3'!A10 | B337: ='REGIÃO 3'!B10 | C337: ='REGIÃO 3'!C10 | D337: ='REGIÃO 3'!D10 | E337: ='REGIÃO 3'!E10 | F337: ='REGIÃO 3'!F10 | G337: ='REGIÃO 3'!G10 | H337: ='REGIÃO 3'!H10 | ... K337: ='REGIÃO 3'!K10 | L337: REGIÃO 3
A338: ='REGIÃO 3'!A11 | B338: ='REGIÃO 3'!B11 | C338: ='REGIÃO 3'!C11 | D338: ='REGIÃO 3'!D11 | E338: ='REGIÃO 3'!E11 | F338: ='REGIÃO 3'!F11 | G338: ='REGIÃO 3'!G11 | H338: ='REGIÃO 3'!H11 | ... K338: ='REGIÃO 3'!K11 | L338: REGIÃO 3
A339: ='REGIÃO 3'!A12 | B339: ='REGIÃO 3'!B12 | C339: ='REGIÃO 3'!C12 | D339: ='REGIÃO 3'!D12 | E339: ='REGIÃO 3'!E12 | F339: ='REGIÃO 3'!F12 | G339: ='REGIÃO 3'!G12 | H339: ='REGIÃO 3'!H12 | ... K339: ='REGIÃO 3'!K12 | L339: REGIÃO 3
A340: ='REGIÃO 3'!A13 | B340: ='REGIÃO 3'!B13 | C340: ='REGIÃO 3'!C13 | D340: ='REGIÃO 3'!D13 | E340: ='REGIÃO 3'!E13 | F340: ='REGIÃO 3'!F13 | G340: ='REGIÃO 3'!G13 | H340: ='REGIÃO 3'!H13 | ... K340: ='REGIÃO 3'!K13 | L340: REGIÃO 3
... A403: ='REGIÃO 3'!A76 | B403: ='REGIÃO 3'!B76 | C403: ='REGIÃO 3'!C76 | D403: ='REGIÃO 3'!D76 | E403: ='REGIÃO 3'!E76 | F403: ='REGIÃO 3'!F76 | G403: ='REGIÃO 3'!G76 | H403: ='REGIÃO 3'!H76 | ... K403: ='REGIÃO 3'!K76 | L403: REGIÃO 3
...

Sheet PAINEL RESUMO
A1: PAINEL RESUMO — GEOPROCESSAMENTO DE TRECHOS
A4: 1. VISÃO GERAL
A5: Total de segmentos (SRE) | B5: =COUNTA(BASE[SRE])-COUNTBLANK(BASE[SRE])-COUNTIF(BASE[SRE],0)
A6: Extensão total (km) | B6: =SUM(BASE[EXTENSÃO REAL (km)])
A7: Extensão média por segmento (km) | B7: =AVERAGEIF(BASE[EXTENSÃO REAL (km)],">0")
A8: Menor extensão (km) | B8: =_xlfn.MINIFS(BASE[EXTENSÃO REAL (km)],BASE[EXTENSÃO REAL (km)],">0")
A9: Maior extensão (km) | B9: =MAX(BASE[EXTENSÃO REAL (km)])
A10: Qtd. de rodovias distintas | B10: {=ROUND(SUMPRODUCT((BASE[RODOVIA]<>0)/COUNTIF(BASE[RODOVIA],BASE[RODOVIA]&"")),0)}
A11: Qtd. de trechos (nº) distintos | B11: {=SUMPRODUCT((BASE[NÚMERO DO TRECHO]<>0)/COUNTIFS(BASE[NÚMERO DO TRECHO],BASE[NÚMERO DO TRECHO]))}
A13: 2. POR REGIÃO / UNIDADE | N13: Dados de apoio dos gráficos
A14: REGIÃO | B14: CIDADE/UNIDADE | C14: SEGMENTOS | D14: EXTENSÃO (km) | E14: % DA REDE | N14: REGIÃO | O14: EXTENSÃO (km)
A15: 1 | B15: =IFERROR(INDEX(BASE[CIDADE],MATCH($A15,BASE[REGIÃO],0)),"") | C15: =COUNTIFS(BASE[REGIÃO],$A15) | D15: =SUMIFS(BASE[EXTENSÃO REAL (km)],BASE[REGIÃO],$A15) | E15: =D15/$B$6 | N15: ="R"&$A15&" - "&$B15 | O15: =$D15
A16: 2 | B16: =IFERROR(INDEX(BASE[CIDADE],MATCH($A16,BASE[REGIÃO],0)),"") | C16: =COUNTIFS(BASE[REGIÃO],$A16) | D16: =SUMIFS(BASE[EXTENSÃO REAL (km)],BASE[REGIÃO],$A16) | E16: =D16/$B$6 | N16: ="R"&$A16&" - "&$B16 | O16: =$D16
A17: 3 | B17: =IFERROR(INDEX(BASE[CIDADE],MATCH($A17,BASE[REGIÃO],0)),"") | C17: =COUNTIFS(BASE[REGIÃO],$A17) | D17: =SUMIFS(BASE[EXTENSÃO REAL (km)],BASE[REGIÃO],$A17) | E17: =D17/$B$6 | N17: ="R"&$A17&" - "&$B17 | O17: =$D17
A18: 11 | B18: =IFERROR(INDEX(BASE[CIDADE],MATCH($A18,BASE[REGIÃO],0)),"") | C18: =COUNTIFS(BASE[REGIÃO],$A18) | D18: =SUMIFS(BASE[EXTENSÃO REAL (km)],BASE[REGIÃO],$A18) | E18: =D18/$B$6 | N18: ="R"&$A18&" - "&$B18 | O18: =$D18
A19: 12 | B19: =IFERROR(INDEX(BASE[CIDADE],MATCH($A19,BASE[REGIÃO],0)),"") | C19: =COUNTIFS(BASE[REGIÃO],$A19) | D19: =SUMIFS(BASE[EXTENSÃO REAL (km)],BASE[REGIÃO],$A19) | E19: =D19/$B$6 | N19: ="R"&$A19&" - "&$B19 | O19: =$D19
A20: 13 | B20: =IFERROR(INDEX(BASE[CIDADE],MATCH($A20,BASE[REGIÃO],0)),"") | C20: =COUNTIFS(BASE[REGIÃO],$A20) | D20: =SUMIFS(BASE[EXTENSÃO REAL (km)],BASE[REGIÃO],$A20) | E20: =D20/$B$6 | N20: ="R"&$A20&" - "&$B20 | O20: =$D20
A21: TOTAL | C21: =SUM(C15:C20) | D21: =SUM(D15:D20) | E21: =SUM(E15:E20)
A23: 3. POR SITUAÇÃO DO SEGMENTO | N23: SITUAÇÃO | O23: EXTENSÃO (km)
A24: SITUAÇÃO | B24: SEGMENTOS | C24: EXTENSÃO (km) | D24: % DA REDE | N24: =$A25 | O24: =$C25
A25: PPS | B25: =COUNTIFS(BASE[SITUAÇÃO],$A25) | C25: =SUMIFS(BASE[EXTENSÃO REAL (km)],BASE[SITUAÇÃO],$A25) | D25: =C25/$B$6 | N25: =$A26 | O25: =$C26
A26: PSU | B26: =COUNTIFS(BASE[SITUAÇÃO],$A26) | C26: =SUMIFS(BASE[EXTENSÃO REAL (km)],BASE[SITUAÇÃO],$A26) | D26: =C26/$B$6 | N26: =$A27 | O26: =$C27
A27: PDU | B27: =COUNTIFS(BASE[SITUAÇÃO],$A27) | C27: =SUMIFS(BASE[EXTENSÃO REAL (km)],BASE[SITUAÇÃO],$A27) | D27: =C27/$B$6 | N27: =$A28 | O27: =$C28
A28: DUP | B28: =COUNTIFS(BASE[SITUAÇÃO],$A28) | C28: =SUMIFS(BASE[EXTENSÃO REAL (km)],BASE[SITUAÇÃO],$A28) | D28: =C28/$B$6 | N28: =$A29 | O28: =$C29
A29: LEN | B29: =COUNTIFS(BASE[SITUAÇÃO],$A29) | C29: =SUMIFS(BASE[EXTENSÃO REAL (km)],BASE[SITUAÇÃO],$A29) | D29: =C29/$B$6 | N29: =$A30 | O29: =$C30
A30: EOP | B30: =COUNTIFS(BASE[SITUAÇÃO],$A30) | C30: =SUMIFS(BASE[EXTENSÃO REAL (km)],BASE[SITUAÇÃO],$A30) | D30: =C30/$B$6
A31: TOTAL | B31: =SUM(B25:B30) | C31: =SUM(C25:C30) | D31: =SUM(D25:D30)
A33: 4. MATRIZ REGIÃO x SITUAÇÃO — EXTENSÃO (km)
A34: REGIÃO | B34: =$A25 | C34: =$A26 | D34: =$A27 | E34: =$A28 | F34: =$A29 | G34: =$A30 | H34: TOTAL
A35: =$A15 | B35: =SUMIFS(BASE[EXTENSÃO REAL (km)],BASE[REGIÃO],$A35,BASE[SITUAÇÃO],B$34) | C35: =SUMIFS(BASE[EXTENSÃO REAL (km)],BASE[REGIÃO],$A35,BASE[SITUAÇÃO],C$34) | D35: =SUMIFS(BASE[EXTENSÃO REAL (km)],BASE[REGIÃO],$A35,BASE[SITUAÇÃO],D$34) | E35: =SUMIFS(BASE[EXTENSÃO REAL (km)],BASE[REGIÃO],$A35,BASE[SITUAÇÃO],E$34) | F35: =SUMIFS(BASE[EXTENSÃO REAL (km)],BASE[REGIÃO],$A35,BASE[SITUAÇÃO],F$34) | G35: =SUMIFS(BASE[EXTENSÃO REAL (km)],BASE[REGIÃO],$A35,BASE[SITUAÇÃO],G$34) | H35: =SUM(B35:G35)
A36: =$A16 | B36: =SUMIFS(BASE[EXTENSÃO REAL (km)],BASE[REGIÃO],$A36,BASE[SITUAÇÃO],B$34) | C36: =SUMIFS(BASE[EXTENSÃO REAL (km)],BASE[REGIÃO],$A36,BASE[SITUAÇÃO],C$34) | D36: =SUMIFS(BASE[EXTENSÃO REAL (km)],BASE[REGIÃO],$A36,BASE[SITUAÇÃO],D$34) | E36: =SUMIFS(BASE[EXTENSÃO REAL (km)],BASE[REGIÃO],$A36,BASE[SITUAÇÃO],E$34) | F36: =SUMIFS(BASE[EXTENSÃO REAL (km)],BASE[REGIÃO],$A36,BASE[SITUAÇÃO],F$34) | G36: =SUMIFS(BASE[EXTENSÃO REAL (km)],BASE[REGIÃO],$A36,BASE[SITUAÇÃO],G$34) | H36: =SUM(B36:G36)
A37: =$A17 | B37: =SUMIFS(BASE[EXTENSÃO REAL (km)],BASE[REGIÃO],$A37,BASE[SITUAÇÃO],B$34) | C37: =SUMIFS(BASE[EXTENSÃO REAL (km)],BASE[REGIÃO],$A37,BASE[SITUAÇÃO],C$34) | D37: =SUMIFS(BASE[EXTENSÃO REAL (km)],BASE[REGIÃO],$A37,BASE[SITUAÇÃO],D$34) | E37: =SUMIFS(BASE[EXTENSÃO REAL (km)],BASE[REGIÃO],$A37,BASE[SITUAÇÃO],E$34) | F37: =SUMIFS(BASE[EXTENSÃO REAL (km)],BASE[REGIÃO],$A37,BASE[SITUAÇÃO],F$34) | G37: =SUMIFS(BASE[EXTENSÃO REAL (km)],BASE[REGIÃO],$A37,BASE[SITUAÇÃO],G$34) | H37: =SUM(B37:G37)
A38: =$A18 | B38: =SUMIFS(BASE[EXTENSÃO REAL (km)],BASE[REGIÃO],$A38,BASE[SITUAÇÃO],B$34) | C38: =SUMIFS(BASE[EXTENSÃO REAL (km)],BASE[REGIÃO],$A38,BASE[SITUAÇÃO],C$34) | D38: =SUMIFS(BASE[EXTENSÃO REAL (km)],BASE[REGIÃO],$A38,BASE[SITUAÇÃO],D$34) | E38: =SUMIFS(BASE[EXTENSÃO REAL (km)],BASE[REGIÃO],$A38,BASE[SITUAÇÃO],E$34) | F38: =SUMIFS(BASE[EXTENSÃO REAL (km)],BASE[REGIÃO],$A38,BASE[SITUAÇÃO],F$34) | G38: =SUMIFS(BASE[EXTENSÃO REAL (km)],BASE[REGIÃO],$A38,BASE[SITUAÇÃO],G$34) | H38: =SUM(B38:G38)
A39: =$A19 | B39: =SUMIFS(BASE[EXTENSÃO REAL (km)],BASE[REGIÃO],$A39,BASE[SITUAÇÃO],B$34) | C39: =SUMIFS(BASE[EXTENSÃO REAL (km)],BASE[REGIÃO],$A39,BASE[SITUAÇÃO],C$34) | D39: =SUMIFS(BASE[EXTENSÃO REAL (km)],BASE[REGIÃO],$A39,BASE[SITUAÇÃO],D$34) | E39: =SUMIFS(BASE[EXTENSÃO REAL (km)],BASE[REGIÃO],$A39,BASE[SITUAÇÃO],E$34) | F39: =SUMIFS(BASE[EXTENSÃO REAL (km)],BASE[REGIÃO],$A39,BASE[SITUAÇÃO],F$34) | G39: =SUMIFS(BASE[EXTENSÃO REAL (km)],BASE[REGIÃO],$A39,BASE[SITUAÇÃO],G$34) | H39: =SUM(B39:G39)
A40: =$A20 | B40: =SUMIFS(BASE[EXTENSÃO REAL (km)],BASE[REGIÃO],$A40,BASE[SITUAÇÃO],B$34) | C40: =SUMIFS(BASE[EXTENSÃO REAL (km)],BASE[REGIÃO],$A40,BASE[SITUAÇÃO],C$34) | D40: =SUMIFS(BASE[EXTENSÃO REAL (km)],BASE[REGIÃO],$A40,BASE[SITUAÇÃO],D$34) | E40: =SUMIFS(BASE[EXTENSÃO REAL (km)],BASE[REGIÃO],$A40,BASE[SITUAÇÃO],E$34) | F40: =SUMIFS(BASE[EXTENSÃO REAL (km)],BASE[REGIÃO],$A40,BASE[SITUAÇÃO],F$34) | G40: =SUMIFS(BASE[EXTENSÃO REAL (km)],BASE[REGIÃO],$A40,BASE[SITUAÇÃO],G$34) | H40: =SUM(B40:G40)
A41: TOTAL | B41: =SUM(B35:B40) | C41: =SUM(C35:C40) | D41: =SUM(D35:D40) | E41: =SUM(E35:E40) | F41: =SUM(F35:F40) | G41: =SUM(G35:G40) | H41: =SUM(H35:H40)
A43: 5. POR RODOVIA
A44: RODOVIA | B44: SEGMENTOS | C44: EXTENSÃO (km) | D44: % DA REDE | E44: RANKING (km)
A45: ACESSO | B45: =COUNTIFS(BASE[RODOVIA],$A45) | C45: =SUMIFS(BASE[EXTENSÃO REAL (km)],BASE[RODOVIA],$A45) | D45: =C45/$B$6 | E45: =RANK(C45,$C$45:$C$114)
A46: TO-010 | B46: =COUNTIFS(BASE[RODOVIA],$A46) | C46: =SUMIFS(BASE[EXTENSÃO REAL (km)],BASE[RODOVIA],$A46) | D46: =C46/$B$6 | E46: =RANK(C46,$C$45:$C$114)
...
